<?xml version="1.0"?>
<!--
  Pelican quadrotor drone description
  Inertias updated from provided chart:
   • body:   m=0.217 kg, Ixx=Iyy=Izz=0.001
   • arm:    m=0.098 kg, Ixx=0.000297, Iyy=0.0001925, Izz=0.00020905
   • rotor:  m=0.009 kg, Ixx=1.898e-05, Ixy=-6.358e-07, Iyy=4.269e-06, Izz=4.283e-06
-->

<robot name="pelican">

  <!-- ==== BASE LINK ==== -->
  <link name="base_link">
    <inertial>
      <mass value="0.217"/>
      <origin xyz="0 0 0" rpy="0 0 0"/>
      <inertia
        ixx="0.001" ixy="0.0" ixz="0.0"
        iyy="0.001" iyz="0.0" izz="0.001"/>
    </inertial>
    <visual>
      <origin xyz="0 0 0" rpy="0 0 0"/>
      <geometry>
        <box size="0.1 0.1 0.2"/>
      </geometry>
      <material name="black">
        <color rgba="0.2 0.2 0.2 1.0"/>
      </material>
    </visual>
    <collision>
      <origin xyz="0 0 0" rpy="0 0 0"/>
      <geometry>
        <box size="0.1 0.1 0.2"/>
      </geometry>
    </collision>
  </link>

  <!-- ==== ROTORS ==== -->

  <link name="front_rotor">
    <inertial>
      <mass value="0.009"/>
      <!-- COM at joint position (0.15, 0, 0.056) -->
      <origin xyz="0.15 0 0.056" rpy="0 0 0"/>
      <inertia
        ixx="0.00001898" ixy="-0.0000006358" ixz="0.0"
        iyy="0.000004269" iyz="0.0" izz="0.000004283"/>
    </inertial>
    <visual>
      <origin xyz="0 0 0" rpy="0 0 0"/>
      <geometry>
        <cylinder radius="0.128" length="0.01"/>
      </geometry>
      <material name="yellow">
        <color rgba="1.0 1.0 0.0 1.0"/>
      </material>
    </visual>
    <collision>
      <origin xyz="0 0 0" rpy="0 0 0"/>
      <geometry>
        <cylinder radius="0.128" length="0.01"/>
      </geometry>
    </collision>
  </link>
  <joint name="front_rotor_joint" type="continuous">
    <parent link="front_arm"/>
    <child link="front_rotor"/>
    <origin xyz="0.15 0 0.05" rpy="0 0 0"/>
    <axis xyz="0 0 1"/>
  </joint>

  <link name="left_rotor">
    <inertial>
      <mass value="0.009"/>
      <origin xyz="0 0.15 0.056" rpy="0 0 0"/>
      <inertia
        ixx="0.00001898" ixy="-0.0000006358" ixz="0.0"
        iyy="0.000004269" iyz="0.0" izz="0.000004283"/>
    </inertial>
    <visual>
      <origin xyz="0 0 0" rpy="0 0 0"/>
      <geometry>
        <cylinder radius="0.128" length="0.01"/>
      </geometry>
      <material name="green">
        <color rgba="0.0 1.0 0.0 1.0"/>
      </material>
    </visual>
    <collision>
      <origin xyz="0 0 0" rpy="0 0 0"/>
      <geometry>
        <cylinder radius="0.128" length="0.01"/>
      </geometry>
    </collision>
  </link>
  <joint name="left_rotor_joint" type="continuous">
    <parent link="left_arm"/>
    <child link="left_rotor"/>
    <origin xyz="0 0.15 0.05" rpy="0 0 0"/>
    <axis xyz="0 0 1"/>
  </joint>

  <link name="back_rotor">
    <inertial>
      <mass value="0.009"/>
      <origin xyz="-0.15 0 0.056" rpy="0 0 0"/>
      <inertia
        ixx="0.00001898" ixy="-0.0000006358" ixz="0.0"
        iyy="0.000004269" iyz="0.0" izz="0.000004283"/>
    </inertial>
    <visual>
      <origin xyz="0 0 0" rpy="0 0 0"/>
      <geometry>
        <cylinder radius="0.128" length="0.01"/>
      </geometry>
      <material name="red">
        <color rgba="1.0 0.0 0.0 1.0"/>
      </material>
    </visual>
    <collision>
      <origin xyz="0 0 0" rpy="0 0 0"/>
      <geometry>
        <cylinder radius="0.128" length="0.01"/>
      </geometry>
    </collision>
  </link>
  <joint name="back_rotor_joint" type="continuous">
    <parent link="back_arm"/>
    <child link="back_rotor"/>
    <origin xyz="-0.15 0 0.05" rpy="0 0 0"/>
    <axis xyz="0 0 1"/>
  </joint>

  <link name="right_rotor">
    <inertial>
      <mass value="0.009"/>
      <origin xyz="0 -0.15 0.056" rpy="0 0 0"/>
      <inertia
        ixx="0.00001898" ixy="-0.0000006358" ixz="0.0"
        iyy="0.000004269" iyz="0.0" izz="0.000004283"/>
    </inertial>
    <visual>
      <origin xyz="0 0 0" rpy="0 0 0"/>
      <geometry>
        <cylinder radius="0.128" length="0.01"/>
      </geometry>
      <material name="blue">
        <color rgba="0.0 0.0 1.0 1.0"/>
      </material>
    </visual>
    <collision>
      <origin xyz="0 0 0" rpy="0 0 0"/>
      <geometry>
        <cylinder radius="0.128" length="0.01"/>
      </geometry>
    </collision>
  </link>
  <joint name="right_rotor_joint" type="continuous">
    <parent link="right_arm"/>
    <child link="right_rotor"/>
    <origin xyz="0 -0.15 0.05" rpy="0 0 0"/>
    <axis xyz="0 0 1"/>
  </joint>

  <!-- ==== ARMS (now with inertial) ==== -->

  <link name="front_arm">
    <inertial>
      <mass value="0.098"/>
      <!-- COM halfway out along X -->
      <origin xyz="0.116 0 0" rpy="0 0 0"/>
      <inertia
        ixx="0.000297" ixy="0.0" ixz="0.0"
        iyy="0.0001925" iyz="0.0" izz="0.00020905"/>
    </inertial>
    <visual>
      <origin xyz="0.075 0 0" rpy="0 1.5708 0"/>
      <geometry>
        <cylinder radius="0.01" length="0.15"/>
      </geometry>
      <material name="black">
        <color rgba="0.2 0.2 0.2 1.0"/>
      </material>
    </visual>
  </link>
  <joint name="front_arm_joint" type="fixed">
    <parent link="base_link"/>
    <child link="front_arm"/>
    <origin xyz="0.060 0 0" rpy="0 0 0"/>
  </joint>

  <link name="left_arm">
    <inertial>
      <mass value="0.098"/>
      <origin xyz="0 0.116 0" rpy="0 0 0"/>
      <inertia
        ixx="0.000297" ixy="0.0" ixz="0.0"
        iyy="0.0001925" iyz="0.0" izz="0.00020905"/>
    </inertial>
    <visual>
      <origin xyz="0 0.075 0" rpy="1.5708 0 0"/>
      <geometry>
        <cylinder radius="0.01" length="0.15"/>
      </geometry>
      <material name="black">
        <color rgba="0.2 0.2 0.2 1.0"/>
      </material>
    </visual>
  </link>
  <joint name="left_arm_joint" type="fixed">
    <parent link="base_link"/>
    <child link="left_arm"/>
    <origin xyz="0 0.060 0" rpy="0 0 0"/>
  </joint>

  <link name="back_arm">
    <inertial>
      <mass value="0.098"/>
      <origin xyz="-0.116 0 0" rpy="0 0 0"/>
      <inertia
        ixx="0.000297" ixy="0.0" ixz="0.0"
        iyy="0.0001925" iyz="0.0" izz="0.00020905"/>
    </inertial>
    <visual>
      <origin xyz="-0.075 0 0" rpy="0 1.5708 0"/>
      <geometry>
        <cylinder radius="0.01" length="0.15"/>
      </geometry>
      <material name="black">
        <color rgba="0.2 0.2 0.2 1.0"/>
      </material>
    </visual>
  </link>
  <joint name="back_arm_joint" type="fixed">
    <parent link="base_link"/>
    <child link="back_arm"/>
    <origin xyz="-0.060 0 0" rpy="0 0 0"/>
  </joint>

  <link name="right_arm">
    <inertial>
      <mass value="0.098"/>
      <origin xyz="0 -0.116 0" rpy="0 0 0"/>
      <inertia
        ixx="0.000297" ixy="0.0" ixz="0.0"
        iyy="0.0001925" iyz="0.0" izz="0.00020905"/>
    </inertial>
    <visual>
      <origin xyz="0 -0.075 0" rpy="1.5708 0 0"/>
      <geometry>
        <cylinder radius="0.01" length="0.15"/>
      </geometry>
      <material name="black">
        <color rgba="0.2 0.2 0.2 1.0"/>
      </material>
    </visual>
  </link>
  <joint name="right_arm_joint" type="fixed">
    <parent link="base_link"/>
    <child link="right_arm"/>
    <origin xyz="0 -0.060 0" rpy="0 0 0"/>
  </joint>

</robot>
